<?xml version="1.0" ?>
<sdf version="1.7">
    <world name="My_world">
        <physics name="1ms" type="ignored">
            <max_step_size>0.001</max_step_size>
            <real_time_factor>1.0</real_time_factor>
        </physics>
        <plugin
            filename="libignition-gazebo-physics-system.so"
            name="ignition::gazebo::systems::Physics">
        </plugin>
        <plugin
            filename="libignition-gazebo-user-commands-system.so"
            name="ignition::gazebo::systems::UserCommands">
        </plugin>
        <plugin
            filename="libignition-gazebo-scene-broadcaster-system.so"
            name="ignition::gazebo::systems::SceneBroadcaster">
        </plugin>

        <gui fullscreen="0">

            <!-- 3D scene -->
            <plugin filename="GzScene3D" name="3D View">
                <ignition-gui>
                <title>3D View</title>
                <property type="bool" key="showTitleBar">false</property>
                <property type="string" key="state">docked</property>
                </ignition-gui>

                <engine>ogre2</engine>
                <scene>scene</scene>
                <ambient_light>0.4 0.4 0.4</ambient_light>
                <background_color>0.8 0.8 0.8</background_color>
                <camera_pose>-6 0 6 0 0.5 0</camera_pose>
            </plugin>

            <!-- World control -->
            <plugin filename="WorldControl" name="World control">
                <ignition-gui>
                <title>World control</title>
                <property type="bool" key="showTitleBar">false</property>
                <property type="bool" key="resizable">false</property>
                <property type="double" key="height">72</property>
                <property type="double" key="width">121</property>
                <property type="double" key="z">1</property>

                <property type="string" key="state">floating</property>
                <anchors target="3D View">
                    <line own="left" target="left"/>
                    <line own="bottom" target="bottom"/>
                </anchors>
                </ignition-gui>

                <play_pause>true</play_pause>
                <step>true</step>
                <start_paused>true</start_paused>
                <service>/world/Moving_robot/control</service>
                <stats_topic>/world/Moving_robot/stats</stats_topic>
            </plugin>

            <!-- World statistics -->
            <plugin filename="WorldStats" name="World stats">
                <ignition-gui>
                <title>World stats</title>
                <property type="bool" key="showTitleBar">false</property>
                <property type="bool" key="resizable">false</property>
                <property type="double" key="height">110</property>
                <property type="double" key="width">290</property>
                <property type="double" key="z">1</property>

                <property type="string" key="state">floating</property>
                <anchors target="3D View">
                    <line own="right" target="right"/>
                    <line own="bottom" target="bottom"/>
                </anchors>
                </ignition-gui>

                <sim_time>true</sim_time>
                <real_time>true</real_time>
                <real_time_factor>true</real_time_factor>
                <iterations>true</iterations>
                <topic>/world/Moving_robot/stats</topic>

            </plugin>

            <!-- Entity tree -->
            <plugin filename="EntityTree" name="Entity tree">
            </plugin>

            <!-- KeyPublisher plugin-->
            <plugin filename="KeyPublisher" name="Key Publisher"/>
            
        </gui>

        <light type="directional" name="sun">
            <cast_shadows>true</cast_shadows>
            <pose>0 0 10 0 0 0</pose>
            <diffuse>0.8 0.8 0.8 1</diffuse>
            <specular>0.2 0.2 0.2 1</specular>
            <attenuation>
                <range>1000</range>
                <constant>0.9</constant>
                <linear>0.01</linear>
                <quadratic>0.001</quadratic>
            </attenuation>
            <direction>-0.5 0.1 -0.9</direction>
        </light>

        <model name="ground_plane">
            <pose> -1 -1 0 0 0 0</pose>
            <static>true</static>
            <link name="link">
                <collision name="collision">
                <geometry>
                    <plane>
                    <normal>0 0 0</normal>
                    </plane>
                </geometry>
                </collision>
                <visual name="visual">
                <geometry>
                    <plane>
                    <normal>0 0 1</normal>
                    <size>100 100</size>
                    </plane>
                </geometry>
                <material>
                    <ambient>0.8 0.8 0.8 1</ambient>
                    <diffuse>0.8 0.8 0.8 1</diffuse>
                    <specular>0.8 0.8 0.8 1</specular>
                </material>
                </visual>
            </link>
        </model>
        <!--<include>
            <pose>0 0 0 0 0 0</pose>
            <uri>
                https://fuel.ignitionrobotics.org/1.0/OpenRobotics/models/COSTAR_HUSKY_SENSOR_CONFIG_1
            </uri>
            <plugin filename="libignition-gazebo-diff-drive-system.so" name="ignition::gazebo::systems::DiffDrive">
                <left_joint>front_left_wheel_joint</left_joint>
                <left_joint>rear_left_wheel_joint</left_joint>
                <right_joint>front_right_wheel_joint</right_joint>
                <right_joint>rear_right_wheel_joint</right_joint>
                <wheel_separation>0.684735</wheel_separation>
                <wheel_radius>0.1651</wheel_radius>
                <topic>/model/costar_husky_sensor_config_1/cmd_vel_relay</topic>
                <min_velocity>-1</min_velocity>
                <max_velocity>1</max_velocity>
                <min_acceleration>-3</min_acceleration>
                <max_acceleration>3</max_acceleration>
            </plugin>

            <plugin filename="libignition-gazebo-pose-publisher-system.so" name="ignition::gazebo::systems::PosePublisher">
                <publish_link_pose>true</publish_link_pose>
                <publish_sensor_pose>true</publish_sensor_pose>
                <publish_collision_pose>false</publish_collision_pose>
                <publish_visual_pose>false</publish_visual_pose>
                <publish_nested_model_pose>true</publish_nested_model_pose>
                <use_pose_vector_msg>true</use_pose_vector_msg>
                <static_publisher>true</static_publisher>
                <static_update_frequency>100</static_update_frequency>
            </plugin>
        </include>-->

        <model name="costar_husky_sensor_config_1">
    <link name="base_link">
      <pose >0 0 0 0 -0 0</pose>
      <inertial>
        <pose >0 0 0.062329 0 -0 0</pose>
        <mass>46.064</mass>
        <inertia>
          <ixx>0.615397</ixx>
          <ixy>-0.0240585</ixy>
          <ixz>-0.120749</ixz>
          <iyy>1.75388</iyy>
          <iyz>-0.0028322</iyz>
          <izz>2.03641</izz>
        </inertia>
      </inertial>
      <collision name="base_link_collision">
        <pose >0 0 0.12 0 0 0</pose>
        <geometry>
          <box>
            <size>0.9874 0.5709 0.05</size>
          </box>
        </geometry>
      </collision>
      <collision name="base_link_collision_bottom">
        <pose >0 0 0.046 0 0 0</pose>
        <geometry>
          <box>
            <size>0.80 0.5709 0.095</size>
          </box>
        </geometry>
      </collision>
      <collision name="base_link_collision_1">
        <pose >0 0 0.185625 0 -0 0</pose>
        <geometry>
          <box>
            <size>0.78992 0.5709 0.12375</size>
          </box>
        </geometry>
      </collision>
      <collision name="base_link_fixed_joint_lump__camera/camera_link_collision_2">
        <pose >0.488 0 0.272 0 -0 0</pose>
        <geometry>
          <box>
            <size>0.0078 0.13 0.0192</size>
          </box>
        </geometry>
        <surface>
          <contact>
            <ode>
              <kp>1e+13</kp>
              <kd>1</kd>
            </ode>
          </contact>
          <friction>
            <ode>
              <mu2>1</mu2>
              <fdir1>0 0 0</fdir1>
            </ode>
          </friction>
        </surface>
      </collision>
      <collision name="base_link_fixed_joint_lump__top_plate_link_collision_3">
        <pose >0.0812 0 0.245 0 -0 0</pose>
        <geometry>
          <mesh>
            <scale>1 1 1</scale>
            <uri>meshes/top_plate.dae</uri>
          </mesh>
        </geometry>
      </collision>
      <collision name="base_link_fixed_joint_lump__top_plate_link_collision_4">
        <pose >0.0812 0 0.245 0 -0 0</pose>
        <geometry>
          <box>
            <size>0.32 0.41 0.09</size>
          </box>
        </geometry>
      </collision>
      <collision name="base_link_fixed_joint_lump__velodyne_base_link_collision_5">
        <pose >0.0012 0 0.71415 0 -0 0</pose>
        <geometry>
          <cylinder>
            <length>0.0717</length>
            <radius>0.0516</radius>
          </cylinder>
        </geometry>
      </collision>
      <visual name="base_link_visual">
        <pose >0 0 0 0 -0 0</pose>
        <geometry>
          <mesh>
            <scale>1 1 1</scale>
            <uri>meshes/base_link.dae</uri>
          </mesh>
        </geometry>
      </visual>
      <visual name="base_link_fixed_joint_lump__camera/camera_link_visual_1">
        <pose >0.438 0 0.272 0 -0 0</pose>
        <geometry>
          <mesh>
            <uri>meshes/realsense.dae</uri>
          </mesh>
        </geometry>
      </visual>
      <visual name="base_link_fixed_joint_lump__cliff_sensor_link_visual_2">
        <pose >0.435 0 0.235 -2.35619 -0 -1.5708</pose>
        <geometry>
          <cylinder>
            <length>0.02</length>
            <radius>0.005</radius>
          </cylinder>
        </geometry>
      </visual>
      <visual name="base_link_fixed_joint_lump__front_bumper_link_visual_3">
        <pose >0.48 0 0.091 0 -0 0</pose>
        <geometry>
          <mesh>
            <scale>1 1 1</scale>
            <uri>meshes/bumper.dae</uri>
          </mesh>
        </geometry>
      </visual>
      <visual name="base_link_fixed_joint_lump__rear_bumper_link_visual_4">
        <pose >-0.48 0 0.091 0 -0 3.14159</pose>
        <geometry>
          <mesh>
            <scale>1 1 1</scale>
            <uri>meshes/bumper.dae</uri>
          </mesh>
        </geometry>
      </visual>
      <visual name="base_link_fixed_joint_lump__top_chassis_link_visual_5">
        <pose >0 0 0 0 -0 0</pose>
        <geometry>
          <mesh>
            <scale>1 1 1</scale>
            <uri>meshes/top_chassis.dae</uri>
          </mesh>
        </geometry>
      </visual>
      <visual name="base_link_fixed_joint_lump__top_plate_link_visual_6">
        <pose >0.0812 0 0.245 0 -0 0</pose>
        <geometry>
          <mesh>
            <scale>1 1 1</scale>
            <uri>meshes/top_plate.dae</uri>
          </mesh>
        </geometry>
      </visual>
      <visual name="base_link_fixed_joint_lump__arch_visual_7">
        <pose >0.0012 0 0.251 0 -0 0</pose>
        <geometry>
          <mesh>
            <scale>1 1 1</scale>
            <uri>meshes/jpl04_arch_nosensor.stl</uri>
          </mesh>
        </geometry>
        <material>
          <ambient>0.8 0.8 0.8 1</ambient>
          <diffuse>0.45 0.45 0.45 1</diffuse>
          <specular>0.8 0.8 0.8 1.0</specular>
        </material>
      </visual>
      <visual name="base_link_fixed_joint_lump__velodyne_base_link_visual_10">
        <pose >0.0012 0 0.6783 0 -0 0</pose>
        <geometry>
          <mesh>
            <scale>1 1 1</scale>
            <uri>meshes/VLP16_base_1.dae</uri>
          </mesh>
        </geometry>
      </visual>
      <visual name="base_link_fixed_joint_lump__velodyne_base_link_visual_11">
        <pose >0.0012 0 0.6783 0 -0 0</pose>
        <geometry>
          <mesh>
            <scale>1 1 1</scale>
            <uri>meshes/VLP16_base_2.dae</uri>
          </mesh>
        </geometry>
      </visual>
      <visual name="base_link_fixed_joint_lump__velodyne_visual_12">
        <pose >0.0012 0 0.6783 0 -0 0</pose>
        <geometry>
          <mesh>
            <scale>1 1 1</scale>
            <uri>meshes/VLP16_scan.dae</uri>
          </mesh>
        </geometry>
      </visual>
      <visual name="base_link_fixed_joint_lump__user_rail_link_visual_13">
        <pose >0.272 0 0.245 0 -0 0</pose>
        <geometry>
          <mesh>
            <scale>1 1 1</scale>
            <uri>meshes/user_rail.dae</uri>
          </mesh>
        </geometry>
      </visual>
      <velocity_decay/>
      <self_collide>0</self_collide>
      <enable_wind>0</enable_wind>
      <kinematic>0</kinematic>
      <sensor name="camera_front" type="rgbd_camera">
        <camera name="camera_front">
            <horizontal_fov>1.0472</horizontal_fov>
            <lens>
                <intrinsics>
                    <!-- fx = fy = width / ( 2 * tan (hfov / 2 ) ) -->
                    <fx>277.1</fx>
                    <fy>277.1</fy>
                    <!-- cx = ( width + 1 ) / 2 -->
                    <cx>160.5</cx>
                    <!-- cy = ( height + 1 ) / 2 -->
                    <cy>120.5</cy>
                    <s>0</s>
                </intrinsics>
            </lens>
            <distortion>
                <k1>0.0</k1>
                <k2>0.0</k2>
                <k3>0.0</k3>
                <p1>0.0</p1>
                <p2>0.0</p2>
                <center>0.5 0.5</center>
            </distortion>
            <image>
                <width>320</width>
                <height>240</height>
                <format>R8G8B8</format>
            </image>
            <clip>
                <near>0.01</near>
                <far>300</far>
            </clip>
            <depth_camera>
              <clip>
                <near>0.1</near>
                <far>10</far>
              </clip>
            </depth_camera>
            <noise>
                <type>gaussian</type>
                <mean>0</mean>
                <stddev>0.007</stddev>
            </noise>
        </camera>
        <always_on>1</always_on>
        <update_rate>20</update_rate>
        <visualize>0</visualize>
        <pose >0.438 0 0.272 0 -0 0</pose>
      </sensor>
      <gravity>1</gravity>
      <velocity_decay/>
      <sensor name="front_cliff_laser" type="gpu_ray">
          <pose>0.435 0 0.235 0 -2.4434589 0</pose>
          <update_rate>50</update_rate>
          <lidar>
              <scan>
                  <horizontal>
                      <samples>1</samples>
                      <resolution>1</resolution>
                      <min_angle>3.141592653589793</min_angle>
                      <max_angle>3.141592653589793</max_angle>
                  </horizontal>
              </scan>
              <range>
                  <min>0.04</min>
                  <max>40</max>
                  <resolution>0.01</resolution>
              </range>
              <noise>
                  <type>gaussian</type>
                  <mean>0</mean>
                  <stddev>0.01</stddev>
              </noise>
          </lidar>
      </sensor>
      <gravity>1</gravity>
      <velocity_decay/>
      <sensor name="front_laser" type="gpu_lidar">
        <visualize>0</visualize>
        <update_rate>10</update_rate>
        <lidar>
          <scan>
            <horizontal>
              <samples>1800</samples>
              <resolution>1</resolution>
              <min_angle>-3.14159</min_angle>
              <max_angle>3.14159</max_angle>
            </horizontal>
            <vertical>
              <samples>16</samples>
              <resolution>1</resolution>
              <min_angle>-0.261799</min_angle>
              <max_angle>0.261799</max_angle>
            </vertical>
          </scan>
          <range>
            <min>0.05</min>
            <max>100</max>
            <resolution>0.01</resolution>
          </range>
          <noise>
            <type>gaussian</type>
            <mean>0</mean>
            <stddev>0.01</stddev>
          </noise>
        </lidar>
        <pose >0.0012 0 0.716 0 -0 0</pose>
      </sensor>
      <light name="flashlight_flashlight_light_source_lamp_light" type="spot">
        <pose >0.48 0.08 0.12 3.141592653589793 1.5707926535897934 -0.0015926535897931</pose>
        <attenuation>
          <range>50</range>
          <linear>0</linear>
          <constant>0.1</constant>
          <quadratic>0.0025</quadratic>
        </attenuation>
        <diffuse>0.8 0.8 0.5 1</diffuse>
        <specular>0.8 0.8 0.5 1</specular>
        <spot>
          <inner_angle>1.2</inner_angle>
          <outer_angle>1.3</outer_angle>
          <falloff>1</falloff>
        </spot>
        <direction>0 0 -1</direction>
      </light>
      <visual name="flashlight_flashlight_light_source_lamp_viz_visual">
        <pose>0.48 0.08 0.12 3.141592653589793 1.5707926535897934 -0.0015926535897931</pose>
        <geometry>
          <cylinder>
            <radius>0.019</radius>
            <length>0.005</length>
          </cylinder>
        </geometry>
        <transparency>0</transparency>
        <material>
          <ambient>1 1 1 1</ambient>
          <diffuse>1 1 1 1</diffuse>
          <specular>1 1 1 1</specular>
          <emissive>1 1 1 1</emissive>
        </material>
      </visual>

      <sensor name="imu_sensor" type="imu">
        <always_on>1</always_on>
        <update_rate>50</update_rate>
        <imu>
                    <angular_velocity>
                        <x>
                            <noise type="gaussian">
                                <mean>0</mean>
                                <stddev>0.009</stddev>
                                <bias_mean>0.00075</bias_mean>
                                <bias_stddev>0.005</bias_stddev>
                                <dynamic_bias_stddev>0.00002</dynamic_bias_stddev>
                                <dynamic_bias_correlation_time>400.0</dynamic_bias_correlation_time>
                                <precision>0.00025</precision>
                            </noise>
                        </x>
                        <y>
                            <noise type="gaussian">
                                <mean>0</mean>
                                <stddev>0.009</stddev>
                                <bias_mean>0.00075</bias_mean>
                                <bias_stddev>0.005</bias_stddev>
                                <dynamic_bias_stddev>0.00002</dynamic_bias_stddev>
                                <dynamic_bias_correlation_time>400.0</dynamic_bias_correlation_time>
                                <precision>0.00025</precision>
                            </noise>
                        </y>
                        <z>
                            <noise type="gaussian">
                                <mean>0</mean>
                                <stddev>0.009</stddev>
                                <bias_mean>0.00075</bias_mean>
                                <bias_stddev>0.005</bias_stddev>
                                <dynamic_bias_stddev>0.00002</dynamic_bias_stddev>
                                <dynamic_bias_correlation_time>400.0</dynamic_bias_correlation_time>
                                <precision>0.00025</precision>
                            </noise>
                        </z>
                    </angular_velocity>
                    <linear_acceleration>
                        <x>
                            <noise type="gaussian">
                                <mean>0</mean>
                                <stddev>0.021</stddev>
                                <bias_mean>0.05</bias_mean>
                                <bias_stddev>0.0075</bias_stddev>
                                <dynamic_bias_stddev>0.000375</dynamic_bias_stddev>
                                <dynamic_bias_correlation_time>175.0</dynamic_bias_correlation_time>
                                <precision>0.005</precision>
                            </noise>
                        </x>
                        <y>
                            <noise type="gaussian">
                                <mean>0</mean>
                                <stddev>0.021</stddev>
                                <bias_mean>0.05</bias_mean>
                                <bias_stddev>0.0075</bias_stddev>
                                <dynamic_bias_stddev>0.000375</dynamic_bias_stddev>
                                <dynamic_bias_correlation_time>175.0</dynamic_bias_correlation_time>
                                <precision>0.005</precision>
                            </noise>
                        </y>
                        <z>
                            <noise type="gaussian">
                                <mean>0</mean>
                                <stddev>0.021</stddev>
                                <bias_mean>0.05</bias_mean>
                                <bias_stddev>0.0075</bias_stddev>
                                <dynamic_bias_stddev>0.000375</dynamic_bias_stddev>
                                <dynamic_bias_correlation_time>175.0</dynamic_bias_correlation_time>
                                <precision>0.005</precision>
                            </noise>
                        </z>
                    </linear_acceleration>
                </imu>
      </sensor>
    </link>
    <link name="front_left_wheel_link">
      <pose >0.256 0.2854 0.03282 0 -0 0</pose>
      <inertial>
        <pose >0 0 0 0 -0 0</pose>
        <mass>2.637</mass>
        <inertia>
          <ixx>0.02467</ixx>
          <ixy>0</ixy>
          <ixz>0</ixz>
          <iyy>0.04411</iyy>
          <iyz>0</iyz>
          <izz>0.02467</izz>
        </inertia>
      </inertial>
      <collision name="front_left_wheel_link_collision">
        <pose >0 0 0 1.5707963267948966 -0 0</pose>
        <geometry>
          <cylinder>
            <length>0.1143</length>
            <radius>0.1651</radius>
          </cylinder>
        </geometry>
        <surface>
          <contact>
            <ode>
              <kp>1e+07</kp>
              <kd>1</kd>
            </ode>
          </contact>
          <friction>
            <ode>
              <mu>0.5</mu>
              <mu2>1</mu2>
              <slip1>0.00062</slip1>
              <slip2>0</slip2>
              <fdir1>0 0 1</fdir1>
            </ode>
          </friction>
        </surface>
      </collision>
      <visual name="front_left_wheel_link_visual">
        <pose >0 0 0 0 -0 0</pose>
        <geometry>
          <mesh>
            <scale>1 1 1</scale>
            <uri>meshes/wheel.dae</uri>
          </mesh>
        </geometry>
      </visual>
      <gravity>1</gravity>
      <velocity_decay/>
    </link>
    <joint name="front_left_wheel_joint" type="revolute">
      <child>front_left_wheel_link</child>
      <parent>base_link</parent>
      <axis>
        <xyz>0 1 0</xyz>
        <limit>
          <lower>-1e+16</lower>
          <upper>1e+16</upper>
        </limit>
        <dynamics>
          <spring_reference>0</spring_reference>
          <spring_stiffness>0</spring_stiffness>
        </dynamics>
        <use_parent_model_frame>1</use_parent_model_frame>
      </axis>
    </joint>
    <link name="front_right_wheel_link">
      <pose >0.256 -0.2854 0.03282 0 -0 0</pose>
      <inertial>
        <pose >0 0 0 0 -0 0</pose>
        <mass>2.637</mass>
        <inertia>
          <ixx>0.02467</ixx>
          <ixy>0</ixy>
          <ixz>0</ixz>
          <iyy>0.04411</iyy>
          <iyz>0</iyz>
          <izz>0.02467</izz>
        </inertia>
      </inertial>
      <collision name="front_right_wheel_link_collision">
        <pose >0 0 0 1.5707963267948966 -0 0</pose>
        <geometry>
          <cylinder>
            <length>0.1143</length>
            <radius>0.1651</radius>
          </cylinder>
        </geometry>
        <surface>
          <contact>
            <ode>
              <kp>1e+07</kp>
              <kd>1</kd>
            </ode>
          </contact>
          <friction>
            <ode>
              <mu>0.5</mu>
              <mu2>1</mu2>
              <slip1>0.00062</slip1>
              <slip2>0</slip2>
              <fdir1>0 0 1</fdir1>
            </ode>
          </friction>
        </surface>
      </collision>
      <visual name="front_right_wheel_link_visual">
        <pose >0 0 0 0 -0 0</pose>
        <geometry>
          <mesh>
            <scale>1 1 1</scale>
            <uri>meshes/wheel.dae</uri>
          </mesh>
        </geometry>
      </visual>
      <gravity>1</gravity>
      <velocity_decay/>
    </link>
    <joint name="front_right_wheel_joint" type="revolute">
      <child>front_right_wheel_link</child>
      <parent>base_link</parent>
      <axis>
        <xyz>0 1 0</xyz>
        <limit>
          <lower>-1e+16</lower>
          <upper>1e+16</upper>
        </limit>
        <dynamics>
          <spring_reference>0</spring_reference>
          <spring_stiffness>0</spring_stiffness>
        </dynamics>
        <use_parent_model_frame>1</use_parent_model_frame>
      </axis>
    </joint>
    <link name="rear_left_wheel_link">
      <pose >-0.256 0.2854 0.03282 0 -0 0</pose>
      <inertial>
        <pose >0 0 0 0 -0 0</pose>
        <mass>2.637</mass>
        <inertia>
          <ixx>0.02467</ixx>
          <ixy>0</ixy>
          <ixz>0</ixz>
          <iyy>0.04411</iyy>
          <iyz>0</iyz>
          <izz>0.02467</izz>
        </inertia>
      </inertial>
      <collision name="rear_left_wheel_link_collision">
        <pose >0 0 0 1.5707963267948966 -0 0</pose>
        <geometry>
          <cylinder>
            <length>0.1143</length>
            <radius>0.1651</radius>
          </cylinder>
        </geometry>
        <surface>
          <contact>
            <ode>
              <kp>1e+07</kp>
              <kd>1</kd>
            </ode>
          </contact>
          <friction>
            <ode>
              <mu>0.5</mu>
              <mu2>1</mu2>
              <slip1>0.00062</slip1>
              <slip2>0</slip2>
              <fdir1>0 0 1</fdir1>
            </ode>
          </friction>
        </surface>
      </collision>
      <visual name="rear_left_wheel_link_visual">
        <pose >0 0 0 0 -0 0</pose>
        <geometry>
          <mesh>
            <scale>1 1 1</scale>
            <uri>meshes/wheel.dae</uri>
          </mesh>
        </geometry>
      </visual>
      <gravity>1</gravity>
      <velocity_decay/>
    </link>
    <joint name="rear_left_wheel_joint" type="revolute">
      <child>rear_left_wheel_link</child>
      <parent>base_link</parent>
      <axis>
        <xyz>0 1 0</xyz>
        <limit>
          <lower>-1e+16</lower>
          <upper>1e+16</upper>
        </limit>
        <dynamics>
          <spring_reference>0</spring_reference>
          <spring_stiffness>0</spring_stiffness>
        </dynamics>
        <use_parent_model_frame>1</use_parent_model_frame>
      </axis>
    </joint>
    <link name="rear_right_wheel_link">
      <pose >-0.256 -0.2854 0.03282 0 -0 0</pose>
      <inertial>
        <pose >0 0 0 0 -0 0</pose>
        <mass>2.637</mass>
        <inertia>
          <ixx>0.02467</ixx>
          <ixy>0</ixy>
          <ixz>0</ixz>
          <iyy>0.04411</iyy>
          <iyz>0</iyz>
          <izz>0.02467</izz>
        </inertia>
      </inertial>
      <collision name="rear_right_wheel_link_collision">
        <pose >0 0 0 1.5707963267948966 -0 0</pose>
        <geometry>
          <cylinder>
            <length>0.1143</length>
            <radius>0.1651</radius>
          </cylinder>
        </geometry>
        <surface>
          <contact>
            <ode>
              <kp>1e+07</kp>
              <kd>1</kd>
            </ode>
          </contact>
          <friction>
            <ode>
              <mu>0.5</mu>
              <mu2>1</mu2>
              <slip1>0.00062</slip1>
              <slip2>0</slip2>
              <fdir1>0 0 1</fdir1>
            </ode>
          </friction>
        </surface>
      </collision>
      <visual name="rear_right_wheel_link_visual">
        <pose >0 0 0 0 -0 0</pose>
        <geometry>
          <mesh>
            <scale>1 1 1</scale>
            <uri>meshes/wheel.dae</uri>
          </mesh>
        </geometry>
      </visual>
      <gravity>1</gravity>
      <velocity_decay/>
    </link>
    <joint name="rear_right_wheel_joint" type="revolute">
      <child>rear_right_wheel_link</child>
      <parent>base_link</parent>
      <axis>
        <xyz>0 1 0</xyz>
        <limit>
          <lower>-1e+16</lower>
          <upper>1e+16</upper>
        </limit>
        <dynamics>
          <spring_reference>0</spring_reference>
          <spring_stiffness>0</spring_stiffness>
        </dynamics>
        <use_parent_model_frame>1</use_parent_model_frame>
      </axis>
    </joint>
    <static>0</static>
        

        <plugin filename="libignition-gazebo-diff-drive-system.so" name="ignition::gazebo::systems::DiffDrive">
                <left_joint>front_left_wheel_joint</left_joint>
                <left_joint>rear_left_wheel_joint</left_joint>
                <right_joint>front_right_wheel_joint</right_joint>
                <right_joint>rear_right_wheel_joint</right_joint>
                <wheel_separation>0.684735</wheel_separation>
                <wheel_radius>0.1651</wheel_radius>
                <topic>/cmd_vel_relay</topic>
                <min_velocity>-1</min_velocity>
                <max_velocity>1</max_velocity>
                <min_acceleration>-3</min_acceleration>
                <max_acceleration>3</max_acceleration>
            </plugin>

            <plugin filename="libignition-gazebo-pose-publisher-system.so" name="ignition::gazebo::systems::PosePublisher">
                <publish_link_pose>true</publish_link_pose>
                <publish_sensor_pose>true</publish_sensor_pose>
                <publish_collision_pose>false</publish_collision_pose>
                <publish_visual_pose>false</publish_visual_pose>
                <publish_nested_model_pose>true</publish_nested_model_pose>
                <use_pose_vector_msg>true</use_pose_vector_msg>
                <static_publisher>true</static_publisher>
                <static_update_frequency>100</static_update_frequency>
            </plugin>
            
  </model>        
  <model name="costar_husky_sensor_config_1_model_2">
    <link name="base_link">
      <pose >0 0 0 0 -0 0</pose>
      <inertial>
        <pose >0 0 0.062329 0 -0 0</pose>
        <mass>46.064</mass>
        <inertia>
          <ixx>0.615397</ixx>
          <ixy>-0.0240585</ixy>
          <ixz>-0.120749</ixz>
          <iyy>1.75388</iyy>
          <iyz>-0.0028322</iyz>
          <izz>2.03641</izz>
        </inertia>
      </inertial>
      <collision name="base_link_collision">
        <pose >0 0 0.12 0 0 0</pose>
        <geometry>
          <box>
            <size>0.9874 0.5709 0.05</size>
          </box>
        </geometry>
      </collision>
      <collision name="base_link_collision_bottom">
        <pose >0 0 0.046 0 0 0</pose>
        <geometry>
          <box>
            <size>0.80 0.5709 0.095</size>
          </box>
        </geometry>
      </collision>
      <collision name="base_link_collision_1">
        <pose >0 0 0.185625 0 -0 0</pose>
        <geometry>
          <box>
            <size>0.78992 0.5709 0.12375</size>
          </box>
        </geometry>
      </collision>
      <collision name="base_link_fixed_joint_lump__camera/camera_link_collision_2">
        <pose >0.488 0 0.272 0 -0 0</pose>
        <geometry>
          <box>
            <size>0.0078 0.13 0.0192</size>
          </box>
        </geometry>
        <surface>
          <contact>
            <ode>
              <kp>1e+13</kp>
              <kd>1</kd>
            </ode>
          </contact>
          <friction>
            <ode>
              <mu2>1</mu2>
              <fdir1>0 0 0</fdir1>
            </ode>
          </friction>
        </surface>
      </collision>
      <collision name="base_link_fixed_joint_lump__top_plate_link_collision_3">
        <pose >0.0812 0 0.245 0 -0 0</pose>
        <geometry>
          <mesh>
            <scale>1 1 1</scale>
            <uri>meshes/top_plate.dae</uri>
          </mesh>
        </geometry>
      </collision>
      <collision name="base_link_fixed_joint_lump__top_plate_link_collision_4">
        <pose >0.0812 0 0.245 0 -0 0</pose>
        <geometry>
          <box>
            <size>0.32 0.41 0.09</size>
          </box>
        </geometry>
      </collision>
      <collision name="base_link_fixed_joint_lump__velodyne_base_link_collision_5">
        <pose >0.0012 0 0.71415 0 -0 0</pose>
        <geometry>
          <cylinder>
            <length>0.0717</length>
            <radius>0.0516</radius>
          </cylinder>
        </geometry>
      </collision>
      <visual name="base_link_visual">
        <pose >0 0 0 0 -0 0</pose>
        <geometry>
          <mesh>
            <scale>1 1 1</scale>
            <uri>meshes/base_link.dae</uri>
          </mesh>
        </geometry>
      </visual>
      <visual name="base_link_fixed_joint_lump__camera/camera_link_visual_1">
        <pose >0.438 0 0.272 0 -0 0</pose>
        <geometry>
          <mesh>
            <uri>meshes/realsense.dae</uri>
          </mesh>
        </geometry>
      </visual>
      <visual name="base_link_fixed_joint_lump__cliff_sensor_link_visual_2">
        <pose >0.435 0 0.235 -2.35619 -0 -1.5708</pose>
        <geometry>
          <cylinder>
            <length>0.02</length>
            <radius>0.005</radius>
          </cylinder>
        </geometry>
      </visual>
      <visual name="base_link_fixed_joint_lump__front_bumper_link_visual_3">
        <pose >0.48 0 0.091 0 -0 0</pose>
        <geometry>
          <mesh>
            <scale>1 1 1</scale>
            <uri>meshes/bumper.dae</uri>
          </mesh>
        </geometry>
      </visual>
      <visual name="base_link_fixed_joint_lump__rear_bumper_link_visual_4">
        <pose >-0.48 0 0.091 0 -0 3.14159</pose>
        <geometry>
          <mesh>
            <scale>1 1 1</scale>
            <uri>meshes/bumper.dae</uri>
          </mesh>
        </geometry>
      </visual>
      <visual name="base_link_fixed_joint_lump__top_chassis_link_visual_5">
        <pose >0 0 0 0 -0 0</pose>
        <geometry>
          <mesh>
            <scale>1 1 1</scale>
            <uri>meshes/top_chassis.dae</uri>
          </mesh>
        </geometry>
      </visual>
      <visual name="base_link_fixed_joint_lump__top_plate_link_visual_6">
        <pose >0.0812 0 0.245 0 -0 0</pose>
        <geometry>
          <mesh>
            <scale>1 1 1</scale>
            <uri>meshes/top_plate.dae</uri>
          </mesh>
        </geometry>
      </visual>
      <visual name="base_link_fixed_joint_lump__arch_visual_7">
        <pose >0.0012 0 0.251 0 -0 0</pose>
        <geometry>
          <mesh>
            <scale>1 1 1</scale>
            <uri>meshes/jpl04_arch_nosensor.stl</uri>
          </mesh>
        </geometry>
        <material>
          <ambient>0.8 0.8 0.8 1</ambient>
          <diffuse>0.45 0.45 0.45 1</diffuse>
          <specular>0.8 0.8 0.8 1.0</specular>
        </material>
      </visual>
      <visual name="base_link_fixed_joint_lump__velodyne_base_link_visual_10">
        <pose >0.0012 0 0.6783 0 -0 0</pose>
        <geometry>
          <mesh>
            <scale>1 1 1</scale>
            <uri>meshes/VLP16_base_1.dae</uri>
          </mesh>
        </geometry>
      </visual>
      <visual name="base_link_fixed_joint_lump__velodyne_base_link_visual_11">
        <pose >0.0012 0 0.6783 0 -0 0</pose>
        <geometry>
          <mesh>
            <scale>1 1 1</scale>
            <uri>meshes/VLP16_base_2.dae</uri>
          </mesh>
        </geometry>
      </visual>
      <visual name="base_link_fixed_joint_lump__velodyne_visual_12">
        <pose >0.0012 0 0.6783 0 -0 0</pose>
        <geometry>
          <mesh>
            <scale>1 1 1</scale>
            <uri>meshes/VLP16_scan.dae</uri>
          </mesh>
        </geometry>
      </visual>
      <visual name="base_link_fixed_joint_lump__user_rail_link_visual_13">
        <pose >0.272 0 0.245 0 -0 0</pose>
        <geometry>
          <mesh>
            <scale>1 1 1</scale>
            <uri>meshes/user_rail.dae</uri>
          </mesh>
        </geometry>
      </visual>
      <velocity_decay/>
      <self_collide>0</self_collide>
      <enable_wind>0</enable_wind>
      <kinematic>0</kinematic>
      <sensor name="camera_front" type="rgbd_camera">
        <camera name="camera_front">
            <horizontal_fov>1.0472</horizontal_fov>
            <lens>
                <intrinsics>
                    <!-- fx = fy = width / ( 2 * tan (hfov / 2 ) ) -->
                    <fx>277.1</fx>
                    <fy>277.1</fy>
                    <!-- cx = ( width + 1 ) / 2 -->
                    <cx>160.5</cx>
                    <!-- cy = ( height + 1 ) / 2 -->
                    <cy>120.5</cy>
                    <s>0</s>
                </intrinsics>
            </lens>
            <distortion>
                <k1>0.0</k1>
                <k2>0.0</k2>
                <k3>0.0</k3>
                <p1>0.0</p1>
                <p2>0.0</p2>
                <center>0.5 0.5</center>
            </distortion>
            <image>
                <width>320</width>
                <height>240</height>
                <format>R8G8B8</format>
            </image>
            <clip>
                <near>0.01</near>
                <far>300</far>
            </clip>
            <depth_camera>
              <clip>
                <near>0.1</near>
                <far>10</far>
              </clip>
            </depth_camera>
            <noise>
                <type>gaussian</type>
                <mean>0</mean>
                <stddev>0.007</stddev>
            </noise>
        </camera>
        <always_on>1</always_on>
        <update_rate>20</update_rate>
        <visualize>0</visualize>
        <pose >0.438 0 0.272 0 -0 0</pose>
      </sensor>
      <gravity>1</gravity>
      <velocity_decay/>
      <sensor name="front_cliff_laser" type="gpu_ray">
          <pose>0.435 0 0.235 0 -2.4434589 0</pose>
          <update_rate>50</update_rate>
          <lidar>
              <scan>
                  <horizontal>
                      <samples>1</samples>
                      <resolution>1</resolution>
                      <min_angle>3.141592653589793</min_angle>
                      <max_angle>3.141592653589793</max_angle>
                  </horizontal>
              </scan>
              <range>
                  <min>0.04</min>
                  <max>40</max>
                  <resolution>0.01</resolution>
              </range>
              <noise>
                  <type>gaussian</type>
                  <mean>0</mean>
                  <stddev>0.01</stddev>
              </noise>
          </lidar>
      </sensor>
      <gravity>1</gravity>
      <velocity_decay/>
      <sensor name="front_laser" type="gpu_lidar">
        <visualize>0</visualize>
        <update_rate>10</update_rate>
        <lidar>
          <scan>
            <horizontal>
              <samples>1800</samples>
              <resolution>1</resolution>
              <min_angle>-3.14159</min_angle>
              <max_angle>3.14159</max_angle>
            </horizontal>
            <vertical>
              <samples>16</samples>
              <resolution>1</resolution>
              <min_angle>-0.261799</min_angle>
              <max_angle>0.261799</max_angle>
            </vertical>
          </scan>
          <range>
            <min>0.05</min>
            <max>100</max>
            <resolution>0.01</resolution>
          </range>
          <noise>
            <type>gaussian</type>
            <mean>0</mean>
            <stddev>0.01</stddev>
          </noise>
        </lidar>
        <pose >0.0012 0 0.716 0 -0 0</pose>
      </sensor>
      <light name="flashlight_flashlight_light_source_lamp_light" type="spot">
        <pose >0.48 0.08 0.12 3.141592653589793 1.5707926535897934 -0.0015926535897931</pose>
        <attenuation>
          <range>50</range>
          <linear>0</linear>
          <constant>0.1</constant>
          <quadratic>0.0025</quadratic>
        </attenuation>
        <diffuse>0.8 0.8 0.5 1</diffuse>
        <specular>0.8 0.8 0.5 1</specular>
        <spot>
          <inner_angle>1.2</inner_angle>
          <outer_angle>1.3</outer_angle>
          <falloff>1</falloff>
        </spot>
        <direction>0 0 -1</direction>
      </light>
      <visual name="flashlight_flashlight_light_source_lamp_viz_visual">
        <pose>0.48 0.08 0.12 3.141592653589793 1.5707926535897934 -0.0015926535897931</pose>
        <geometry>
          <cylinder>
            <radius>0.019</radius>
            <length>0.005</length>
          </cylinder>
        </geometry>
        <transparency>0</transparency>
        <material>
          <ambient>1 1 1 1</ambient>
          <diffuse>1 1 1 1</diffuse>
          <specular>1 1 1 1</specular>
          <emissive>1 1 1 1</emissive>
        </material>
      </visual>

      <sensor name="imu_sensor" type="imu">
        <always_on>1</always_on>
        <update_rate>50</update_rate>
        <imu>
                    <angular_velocity>
                        <x>
                            <noise type="gaussian">
                                <mean>0</mean>
                                <stddev>0.009</stddev>
                                <bias_mean>0.00075</bias_mean>
                                <bias_stddev>0.005</bias_stddev>
                                <dynamic_bias_stddev>0.00002</dynamic_bias_stddev>
                                <dynamic_bias_correlation_time>400.0</dynamic_bias_correlation_time>
                                <precision>0.00025</precision>
                            </noise>
                        </x>
                        <y>
                            <noise type="gaussian">
                                <mean>0</mean>
                                <stddev>0.009</stddev>
                                <bias_mean>0.00075</bias_mean>
                                <bias_stddev>0.005</bias_stddev>
                                <dynamic_bias_stddev>0.00002</dynamic_bias_stddev>
                                <dynamic_bias_correlation_time>400.0</dynamic_bias_correlation_time>
                                <precision>0.00025</precision>
                            </noise>
                        </y>
                        <z>
                            <noise type="gaussian">
                                <mean>0</mean>
                                <stddev>0.009</stddev>
                                <bias_mean>0.00075</bias_mean>
                                <bias_stddev>0.005</bias_stddev>
                                <dynamic_bias_stddev>0.00002</dynamic_bias_stddev>
                                <dynamic_bias_correlation_time>400.0</dynamic_bias_correlation_time>
                                <precision>0.00025</precision>
                            </noise>
                        </z>
                    </angular_velocity>
                    <linear_acceleration>
                        <x>
                            <noise type="gaussian">
                                <mean>0</mean>
                                <stddev>0.021</stddev>
                                <bias_mean>0.05</bias_mean>
                                <bias_stddev>0.0075</bias_stddev>
                                <dynamic_bias_stddev>0.000375</dynamic_bias_stddev>
                                <dynamic_bias_correlation_time>175.0</dynamic_bias_correlation_time>
                                <precision>0.005</precision>
                            </noise>
                        </x>
                        <y>
                            <noise type="gaussian">
                                <mean>0</mean>
                                <stddev>0.021</stddev>
                                <bias_mean>0.05</bias_mean>
                                <bias_stddev>0.0075</bias_stddev>
                                <dynamic_bias_stddev>0.000375</dynamic_bias_stddev>
                                <dynamic_bias_correlation_time>175.0</dynamic_bias_correlation_time>
                                <precision>0.005</precision>
                            </noise>
                        </y>
                        <z>
                            <noise type="gaussian">
                                <mean>0</mean>
                                <stddev>0.021</stddev>
                                <bias_mean>0.05</bias_mean>
                                <bias_stddev>0.0075</bias_stddev>
                                <dynamic_bias_stddev>0.000375</dynamic_bias_stddev>
                                <dynamic_bias_correlation_time>175.0</dynamic_bias_correlation_time>
                                <precision>0.005</precision>
                            </noise>
                        </z>
                    </linear_acceleration>
                </imu>
      </sensor>
    </link>
    <link name="front_left_wheel_link">
      <pose >0.256 0.2854 0.03282 0 -0 0</pose>
      <inertial>
        <pose >0 0 0 0 -0 0</pose>
        <mass>2.637</mass>
        <inertia>
          <ixx>0.02467</ixx>
          <ixy>0</ixy>
          <ixz>0</ixz>
          <iyy>0.04411</iyy>
          <iyz>0</iyz>
          <izz>0.02467</izz>
        </inertia>
      </inertial>
      <collision name="front_left_wheel_link_collision">
        <pose >0 0 0 1.5707963267948966 -0 0</pose>
        <geometry>
          <cylinder>
            <length>0.1143</length>
            <radius>0.1651</radius>
          </cylinder>
        </geometry>
        <surface>
          <contact>
            <ode>
              <kp>1e+07</kp>
              <kd>1</kd>
            </ode>
          </contact>
          <friction>
            <ode>
              <mu>0.5</mu>
              <mu2>1</mu2>
              <slip1>0.00062</slip1>
              <slip2>0</slip2>
              <fdir1>0 0 1</fdir1>
            </ode>
          </friction>
        </surface>
      </collision>
      <visual name="front_left_wheel_link_visual">
        <pose >0 0 0 0 -0 0</pose>
        <geometry>
          <mesh>
            <scale>1 1 1</scale>
            <uri>meshes/wheel.dae</uri>
          </mesh>
        </geometry>
      </visual>
      <gravity>1</gravity>
      <velocity_decay/>
    </link>
    <joint name="front_left_wheel_joint" type="revolute">
      <child>front_left_wheel_link</child>
      <parent>base_link</parent>
      <axis>
        <xyz>0 1 0</xyz>
        <limit>
          <lower>-1e+16</lower>
          <upper>1e+16</upper>
        </limit>
        <dynamics>
          <spring_reference>0</spring_reference>
          <spring_stiffness>0</spring_stiffness>
        </dynamics>
        <use_parent_model_frame>1</use_parent_model_frame>
      </axis>
    </joint>
    <link name="front_right_wheel_link">
      <pose >0.256 -0.2854 0.03282 0 -0 0</pose>
      <inertial>
        <pose >0 0 0 0 -0 0</pose>
        <mass>2.637</mass>
        <inertia>
          <ixx>0.02467</ixx>
          <ixy>0</ixy>
          <ixz>0</ixz>
          <iyy>0.04411</iyy>
          <iyz>0</iyz>
          <izz>0.02467</izz>
        </inertia>
      </inertial>
      <collision name="front_right_wheel_link_collision">
        <pose >0 0 0 1.5707963267948966 -0 0</pose>
        <geometry>
          <cylinder>
            <length>0.1143</length>
            <radius>0.1651</radius>
          </cylinder>
        </geometry>
        <surface>
          <contact>
            <ode>
              <kp>1e+07</kp>
              <kd>1</kd>
            </ode>
          </contact>
          <friction>
            <ode>
              <mu>0.5</mu>
              <mu2>1</mu2>
              <slip1>0.00062</slip1>
              <slip2>0</slip2>
              <fdir1>0 0 1</fdir1>
            </ode>
          </friction>
        </surface>
      </collision>
      <visual name="front_right_wheel_link_visual">
        <pose >0 0 0 0 -0 0</pose>
        <geometry>
          <mesh>
            <scale>1 1 1</scale>
            <uri>meshes/wheel.dae</uri>
          </mesh>
        </geometry>
      </visual>
      <gravity>1</gravity>
      <velocity_decay/>
    </link>
    <joint name="front_right_wheel_joint" type="revolute">
      <child>front_right_wheel_link</child>
      <parent>base_link</parent>
      <axis>
        <xyz>0 1 0</xyz>
        <limit>
          <lower>-1e+16</lower>
          <upper>1e+16</upper>
        </limit>
        <dynamics>
          <spring_reference>0</spring_reference>
          <spring_stiffness>0</spring_stiffness>
        </dynamics>
        <use_parent_model_frame>1</use_parent_model_frame>
      </axis>
    </joint>
    <link name="rear_left_wheel_link">
      <pose >-0.256 0.2854 0.03282 0 -0 0</pose>
      <inertial>
        <pose >0 0 0 0 -0 0</pose>
        <mass>2.637</mass>
        <inertia>
          <ixx>0.02467</ixx>
          <ixy>0</ixy>
          <ixz>0</ixz>
          <iyy>0.04411</iyy>
          <iyz>0</iyz>
          <izz>0.02467</izz>
        </inertia>
      </inertial>
      <collision name="rear_left_wheel_link_collision">
        <pose >0 0 0 1.5707963267948966 -0 0</pose>
        <geometry>
          <cylinder>
            <length>0.1143</length>
            <radius>0.1651</radius>
          </cylinder>
        </geometry>
        <surface>
          <contact>
            <ode>
              <kp>1e+07</kp>
              <kd>1</kd>
            </ode>
          </contact>
          <friction>
            <ode>
              <mu>0.5</mu>
              <mu2>1</mu2>
              <slip1>0.00062</slip1>
              <slip2>0</slip2>
              <fdir1>0 0 1</fdir1>
            </ode>
          </friction>
        </surface>
      </collision>
      <visual name="rear_left_wheel_link_visual">
        <pose >0 0 0 0 -0 0</pose>
        <geometry>
          <mesh>
            <scale>1 1 1</scale>
            <uri>meshes/wheel.dae</uri>
          </mesh>
        </geometry>
      </visual>
      <gravity>1</gravity>
      <velocity_decay/>
    </link>
    <joint name="rear_left_wheel_joint" type="revolute">
      <child>rear_left_wheel_link</child>
      <parent>base_link</parent>
      <axis>
        <xyz>0 1 0</xyz>
        <limit>
          <lower>-1e+16</lower>
          <upper>1e+16</upper>
        </limit>
        <dynamics>
          <spring_reference>0</spring_reference>
          <spring_stiffness>0</spring_stiffness>
        </dynamics>
        <use_parent_model_frame>1</use_parent_model_frame>
      </axis>
    </joint>
    <link name="rear_right_wheel_link">
      <pose >-0.256 -0.2854 0.03282 0 -0 0</pose>
      <inertial>
        <pose >0 0 0 0 -0 0</pose>
        <mass>2.637</mass>
        <inertia>
          <ixx>0.02467</ixx>
          <ixy>0</ixy>
          <ixz>0</ixz>
          <iyy>0.04411</iyy>
          <iyz>0</iyz>
          <izz>0.02467</izz>
        </inertia>
      </inertial>
      <collision name="rear_right_wheel_link_collision">
        <pose >0 0 0 1.5707963267948966 -0 0</pose>
        <geometry>
          <cylinder>
            <length>0.1143</length>
            <radius>0.1651</radius>
          </cylinder>
        </geometry>
        <surface>
          <contact>
            <ode>
              <kp>1e+07</kp>
              <kd>1</kd>
            </ode>
          </contact>
          <friction>
            <ode>
              <mu>0.5</mu>
              <mu2>1</mu2>
              <slip1>0.00062</slip1>
              <slip2>0</slip2>
              <fdir1>0 0 1</fdir1>
            </ode>
          </friction>
        </surface>
      </collision>
      <visual name="rear_right_wheel_link_visual">
        <pose >0 0 0 0 -0 0</pose>
        <geometry>
          <mesh>
            <scale>1 1 1</scale>
            <uri>meshes/wheel.dae</uri>
          </mesh>
        </geometry>
      </visual>
      <gravity>1</gravity>
      <velocity_decay/>
    </link>
    <joint name="rear_right_wheel_joint" type="revolute">
      <child>rear_right_wheel_link</child>
      <parent>base_link</parent>
      <axis>
        <xyz>0 1 0</xyz>
        <limit>
          <lower>-1e+16</lower>
          <upper>1e+16</upper>
        </limit>
        <dynamics>
          <spring_reference>0</spring_reference>
          <spring_stiffness>0</spring_stiffness>
        </dynamics>
        <use_parent_model_frame>1</use_parent_model_frame>
      </axis>
    </joint>
    <static>0</static>
        

        <plugin filename="libignition-gazebo-diff-drive-system.so" name="ignition::gazebo::systems::DiffDrive">
                <left_joint>front_left_wheel_joint</left_joint>
                <left_joint>rear_left_wheel_joint</left_joint>
                <right_joint>front_right_wheel_joint</right_joint>
                <right_joint>rear_right_wheel_joint</right_joint>
                <wheel_separation>0.684735</wheel_separation>
                <wheel_radius>0.1651</wheel_radius>
                <topic>/cmd_vel_relay/bot2</topic>
                <min_velocity>-1</min_velocity>
                <max_velocity>1</max_velocity>
                <min_acceleration>-3</min_acceleration>
                <max_acceleration>3</max_acceleration>
            </plugin>
            
            <plugin filename="libignition-gazebo-pose-publisher-system.so" name="ignition::gazebo::systems::PosePublisher">
                <publish_link_pose>true</publish_link_pose>
                <publish_sensor_pose>true</publish_sensor_pose>
                <publish_collision_pose>false</publish_collision_pose>
                <publish_visual_pose>false</publish_visual_pose>
                <publish_nested_model_pose>true</publish_nested_model_pose>
                <use_pose_vector_msg>true</use_pose_vector_msg>
                <static_publisher>true</static_publisher>
                <static_update_frequency>100</static_update_frequency>
            </plugin>
            
  </model>  
        
        

    </world>
</sdf>
